Workbook
Name Beginning_Reserve_Balance_Date: 'Property Info'!$B$15
Name City_State: Expenditures!$N$6
Name City_State: 'Funding Plan'!$C$6
Name Client_City: 'Property Info'!$B$3
Name Client_Long: 'Property Info'!$B$2
Name Client_State: 'Property Info'!$B$4
Name contributions_year0: 'Funding Plan'!$E$8
Name contributions_year1: 'Funding Plan'!$F$8
Name contributions_year10: 'Funding Plan'!$O$8
Name contributions_year11: 'Funding Plan'!$P$8
Name contributions_year12: 'Funding Plan'!$Q$8
Name contributions_year13: 'Funding Plan'!$R$8
Name contributions_year14: 'Funding Plan'!$S$8
Name contributions_year15: 'Funding Plan'!$T$8
Name contributions_year16: 'Funding Plan'!$F$29
Name contributions_year17: 'Funding Plan'!$G$29
Name contributions_year18: 'Funding Plan'!$H$29
Name contributions_year19: 'Funding Plan'!$I$29
Name contributions_year2: 'Funding Plan'!$G$8
Name contributions_year20: 'Funding Plan'!$J$29
Name contributions_year21: 'Funding Plan'!$K$29
Name contributions_year22: 'Funding Plan'!$L$29
Name contributions_year23: 'Funding Plan'!$M$29
Name contributions_year24: 'Funding Plan'!$N$29
Name contributions_year25: 'Funding Plan'!$O$29
Name contributions_year26: 'Funding Plan'!$P$29
Name contributions_year27: 'Funding Plan'!$Q$29
Name contributions_year28: 'Funding Plan'!$R$29
Name contributions_year29: 'Funding Plan'!$S$29
Name contributions_year3: 'Funding Plan'!$H$8
Name contributions_year30: 'Funding Plan'!$T$29
Name contributions_year4: 'Funding Plan'!$I$8
Name contributions_year5: 'Funding Plan'!$J$8
Name contributions_year6: 'Funding Plan'!$K$8
Name contributions_year7: 'Funding Plan'!$L$8
Name contributions_year8: 'Funding Plan'!$M$8
Name contributions_year9: 'Funding Plan'!$N$8
Name Currency_Symbol: 'Property Info'!$B$22
Name Current_Fiscal_Year: 'Property Info'!$B$10
Name Date_of_Inspection: 'Property Info'!$B$9
Name expenditures0: Expenditures!$X$22
Name expenditures0: #REF!
Name expenditures1: Expenditures!$Y$22
Name expenditures1: #REF!
Name expenditures10: Expenditures!$AH$22
Name expenditures10: #REF!
Name expenditures11: Expenditures!$AI$22
Name expenditures11: #REF!
Name expenditures12: Expenditures!$AJ$22
Name expenditures12: #REF!
Name expenditures13: Expenditures!$AK$22
Name expenditures13: #REF!
Name expenditures14: Expenditures!$AL$22
Name expenditures14: #REF!
Name expenditures15: Expenditures!$AM$22
Name expenditures15: #REF!
Name expenditures16: Expenditures!$AN$22
Name expenditures16: #REF!
Name expenditures17: Expenditures!$AO$22
Name expenditures17: #REF!

Sheet Property Info
A1: Version: | B1: v7.0
A2: Association Name: | B2: The Villas at Amarra Drive Condominium Community, Inc.
A3: City: | B3: Austin
A4: State: | B4: Texas
A5: Reference Number: | B5: 253212
A6: Length of Study (Years): | B6: 30
A7: Number of Units: | B7: 20
A8: Number of Buildings: | B8: 1
A9: Date of Inspection: | B9: 46042
A10: Current Fiscal Year: | B10: 2026
A11: Fiscal Year Beginning: | B11: 46023
A12: First Year of Recommendation: | B12: 2027
A13: Remaining Budgeted Intervals: | B13: 11
A14: Remaining Budgeted Months of Interest: | B14: 11
A15: Beginning Reserve Balance Date: | B15: 46053
A16: Reserve Balance Projected: | B16: No
A17: Near Term Inflation: | B17: 0.032
A18: Last Year of Near Term Inflation: | B18: 2067
A19: Remaining Study Inflation: | B19: 0.032
A20: Interest: | B20: 0.02
A21: Frequency of Contributions: | B21: 12
A22: Currency Symbol: | B22: $
A23: Rounded_by: | B23: 100
A24: Operating_Budget: | B24: 156000
A25: Property_Type: | B25: homeowners association
B26: ="©"&Current_Fiscal_Year&" Reserve Advisors LLC. All rights reserved. Any unauthorized copying, alteration, distribution, transmission, display or other use of this spreadsheet and its contents, "&"data or formula are strictly prohibited."&" This spreadsheet is licensed to you pursuant to (and is subject in all respects to the terms and conditions of) your agreement with Reserve Advisors LLC. "&"Reserve Advisors LLC does not make, and expressly disclaims, any representations or warranties (express or implied), including, "&"without limitation, as to the accuracy or timeliness of information prepared by you or any third parties, whether linked to this spreadsheet or incorporated herein."&" We encourage you to contact us at www.reserveadvisors.com with any questions." -> ©2026 Reserve Advisors LLC. All rights reserved. Any unauthorized copying, alteration, distribution, transmission, display or other use of this spreadsheet and its contents, data or formula are strictly prohibited. This spreadsheet is licensed to you pursuant to (and is subject in all respects to the terms and conditions of) your agreement with Reserve Advisors LLC. Reserve Advisors LLC does not make, and expressly disclaims, any representations or warranties (express or implied), including, without limitation, as to the accuracy or timeliness of information prepared by you or any third parties, whether linked to this spreadsheet or incorporated herein. We encourage you to contact us at www.reserveadvisors.com with any questions.

Sheet Use Instructions
A7: Expenditure Sheet Controls:
A8: Column Range Address | B8: Column Name | C8: Description
A9: Column C | B9: Frequency of Events | C9: If an event is phased using Column E, the user can control the years in between each phase of the component.
A10: Column E | B10: Events Per Phase | C10: This value can be edited to phase an event. Ex: The user wants to include three phases of an event. The user would change the value in Column E to a value of "3".
A11: Column F | B11: Next Full Replacement | C11: This value can be edited to change the first year occurrence of an event.
A12: Column G | B12: Useful Life | C12: This value can be edited to change how often the event will occur after the initial event. Ex: The user wants to change the frequency of a replacement event from 20 years to 15 years. The user would change the value in Column G to a value of "15".
A13: Column R | B13: Costs $ (Unit) | C13: This value can be edited to update the per unit cost for a component. Ex: The user wants to update the unit cost for a component from $800.00 to $1,200.00. The user would change the value in Column R to a value of "1,200.00".
A14: Column S | B14: Costs, $ (Percentage Ownership) | C14: IF APPLICABLE to your study, this column includes the percentage of ownership that the entity is responsible to pay.
A15: Columns X through BB | B15: Years of Expenditures | C15: To apply an additional inflated expense in any year within these columns, Copy and Paste the Formula from cell Y5 onto the Line Item and in the year you would like to show the inflated cost.
A17: Funding Sheet Controls
A18: Range Address | B18: Column Name | C18: Description
A19: Cell L21 | B19: Single Increase | C19: A dollar amount entered in this cell will show up in the Funding Plan as a Single Year increase in the first non-budgeted year.
A20: Cells N21 and N22 | B20: Phased Increase | C20: A dollar amount (N21) and number of years (N22) entered in these cells will increase Reserve Contributions by the amount specified beginning in the first non-budgeted year and concluding in the number of years entered]
A21: Cells P21, P22 and P23 | B21: Stable | C21: A dollar amount (P21), beginning year (P22) and ending year (P23) will stabilize Reserve Contributions over the specified year range
A22: Cells R21 and R22 | B22: Decrease | C22: A dollar amount (R21), and a year (R22) will decrease the contributions to the specified amount in the specified year
A23: Cells T21 and T22 | B23: 2nd Decrease | C23: A dollar amount (T21), and a year (T22) will decrease the contributions to the specified amount in the specified year

Sheet Expenditures
Y1: Explanatory Notes: | AJ1: =IF(COUNTIFS($J$10:J21,"<>0",$W$10:W21,"=0"),BB9 & "+","")
N2: RESERVE EXPENDITURES | X2: 1) | Y2: =IF(Inflation=secondaryInflation,Inflation,secondaryInflation) -> 0.032 | Z2: =IF(Inflation=secondaryInflation,"is the estimated Inflation Rate for estimating Future Replacement Costs.","is the estimated Inflation Rate through "&secondaryInflationYear&".") -> is the estimated Inflation Rate for estimating Future Replacement Costs.
X3: 2) | Y3: FY2026 | Z3: is Fiscal Year beginning January 1, 2026 and ending December 31, 2026.
N4: The Villas at Amarra Drive | X4: =IF(Y4<>"","3)","") | Y4: =IF(COUNTIFS($J$10:J21,"<>0",$W$10:W21,"=0"),BB9+1 & "+","") | Z4: =IF($Y$4<>"","indicates a component which is considered long-lived","")
N5: Condominium Community, Inc. | X5: =IF(X4="","","4)") | Y5: =IF($L5="","Formula",IF(secondaryInflationYear- Current_Fiscal_Year >=Y$8,ROUND($L5* $R5*$S5*((1 + Y$7)^Y$8),1),ROUND($L5* $R5*$S5*(((1+secondaryInflation)^(secondaryInflationYear-Current_Fiscal_Year)) * ((1+Y$7)^(Y$8-(secondaryInflationYear - Current_Fiscal_Year)))),1))) -> Formula | Z5: < Copy Formula to a blank cell to show an Inflated Cost outside the regular timing intervals defined by columns B through G
N6: Austin, TX
O7: Estimated | P7: Life Analysis, | R7: Costs, $ | W7: Percentage | X7: =IF(secondaryInflationYear>=X$9,secondaryInflation,Inflation) -> 0.032 | Y7: =IF(secondaryInflationYear>=Y$9,secondaryInflation,Inflation) -> 0.032 | Z7: =IF(secondaryInflationYear>=Z$9,secondaryInflation,Inflation) -> 0.032 | AA7: =IF(secondaryInflationYear>=AA$9,secondaryInflation,Inflation) -> 0.032 | AB7: =IF(secondaryInflationYear>=AB$9,secondaryInflation,Inflation) -> 0.032 | AC7: =IF(secondaryInflationYear>=AC$9,secondaryInflation,Inflation) -> 0.032 | AD7: =IF(secondaryInflationYear>=AD$9,secondaryInflation,Inflation) -> 0.032 | AE7: =IF(secondaryInflationYear>=AE$9,secondaryInflation,Inflation) -> 0.032 | ... BB7: =IF(secondaryInflationYear>=BB$9,secondaryInflation,Inflation) -> 0.032
B8: Partial | C8: Frequency | D8: Length | E8: Events | F8: Next Full | G8: Useful | H8: Round | J8: Line | K8: Total | L8: Per Phase | O8: 1st Year of | P8: Years | R8: Unit | S8: Percentage | T8: Per Phase | U8: Total | V8: 30-Year Total | W8: of Future | X8: 0 | Y8: 1 | Z8: 2 | AA8: 3 | AB8: 4 | AC8: 5 | AD8: 6 | AE8: 7 | AF8: 8 | AG8: 9 | AH8: 10 | AI8: 11 | AJ8: 12 | AK8: 13 | AL8: 14 | AM8: 15 | AN8: 16 | AO8: 17 | AP8: 18 | AQ8: 19 | AR8: 20 | AS8: 21 | AT8: 22 | AU8: 23 | AV8: 24 | AW8: 25 | AX8: 26 | AY8: 27 | AZ8: 28 | BA8: 29 | BB8: 30
B9: Quantity | C9: of Events | D9: of Phase | E9: Per Phase | F9: Repl. | G9: Life | H9: Phase | J9: Item | K9: Quantity | L9: Quantity | M9: Units | N9: Reserve Component Inventory | O9: Event | P9: Useful | Q9: Remaining | R9: ="(" & Current_Fiscal_Year & ")" -> (2026) | S9: Ownership | T9: ="(" & Current_Fiscal_Year & ")" -> (2026) | U9: ="(" & Current_Fiscal_Year & ")" -> (2026) | V9: (Inflated) | W9: Expenditures | X9: ='Property Info'!B10 -> 2026 | Y9: =X9+1 -> 2027 | Z9: =Y9+1 -> 2028 | AA9: =Z9+1 -> 2029 | AB9: =AA9+1 -> 2030 | AC9: =AB9+1 -> 2031 | AD9: =AC9+1 -> 2032 | AE9: =AD9+1 -> 2033 | AF9: =AE9+1 -> 2034 | ... BB9: =BA9+1 -> 2056
B10: - | C10: - | D10: - | E10: - | F10: - | G10: - | J10: - | L10: - | M10: - | N10: - | O10: - | P10: - | Q10: - | R10: - | S10: - | T10: - | U10: - | V10: - | W10: - | X10: - | Y10: - | Z10: - | AA10: - | AB10: - | AC10: - | AD10: - | AE10: - | AF10: - | AG10: - | AH10: - | AI10: - | AJ10: - | AK10: - | AL10: - | AM10: - | AN10: - | AO10: - | AP10: - | AQ10: - | AR10: - | AS10: - | AT10: - | AU10: - | AV10: - | AW10: - | AX10: - | AY10: - | AZ10: - | BA10: - | BB10: -
A11: =IF(OFFSET($B11,IF(AND($K11=0,NOT(ISBLANK($K11))),-4,-3),-1)=0,1,0) -> 1 | N11: Property Site Elements
A12: =IF(OFFSET($B12,IF(AND($K12=0,NOT(ISBLANK($K12))),-4,-3),-1)=0,1,0) -> 1 | B12: 1 | C12: 1 | D12: =(($E12-1)*$C12)+1 -> 1 | E12: 1 | F12: 2031 | G12: 5 | H12: 0.01 | J12: 4.02 | K12: 4200 | L12: =IF(M12="Allowance",1,ROUND(K12*B12/E12/H12,0)*H12) -> 4200 | M12: Square Yards | N12: Asphalt Pavement, Streets, Crack Repairs, Patch and Seal Coat | O12: =IF($F12>$BB$9,$F12,Current_Fiscal_Year+MATCH(TRUE,INDEX($X12:$BB12<>"",0),0)-1) -> 2031 | P12: 3 to 5 | Q12: =$O12-Current_Fiscal_Year&IF($B12<1," to "&Study_Length&"+",IF( $E12>1," to "&IF($O12-Current_Fiscal_Year+$D12-1>Study_Length,Study_Length&"+",$O12-Current_Fiscal_Year+$D12-1),"")) -> 5 | R12: 3 | S12: 1 | T12: =$L12*$R12*$S12 -> 12600 | U12: =$K12*$R12*$S12 -> 12600 | V12: =SUM(OFFSET($X12,,,1,Study_Length+1)) -> 115780.3 | W12: =$V12/Total_Study_Expenditures -> 0.14431038 | X12: =IFERROR(IF(OR(X$8 = ($F12 - Current_Fiscal_Year),AND(MOD($F12-X$9,$G12)=0,X$9>$F12)),IF(secondaryInflationYear- Current_Fiscal_Year >=X$8,ROUND($L12* $R12*$S12*((1 + X$7)^X$8),1),ROUND($L12* $R12*$S12*(((1+secondaryInflation)^(secondaryInflationYear-Current_Fiscal_Year)) * ((1+X$7)^(X$8-(secondaryInflationYear - Current_Fiscal_Year)))),1)),IF(AND($D12<>1,X$8 > ($F12 - Current_Fiscal_Year),(X$8 - (($F12 - Current_Fiscal_Year)+$G12*INT(((X$8 - ($F12 - Current_Fiscal_Year)) / $G12))))/((($D12 - $E12)/($E12-1))+1) = INT((X$8 - (($F12 - Current_Fiscal_Year)+$G12*INT(((X$8 - ($F12 - Current_Fiscal_Year)) / $G12))))/((($D12 - $E12)/($E12-1))+1)), (X$8 - (($F12 - Current_Fiscal_Year)+$G12*INT(((X$8 - ($F12 - Current_Fiscal_Year)) / $G12)))) <$D12),IF(secondaryInflationYear- Current_Fiscal_Year >=X$8,ROUND($L12* $R12*$S12*((1 + X$7)^X$8),1),ROUND($L12* $R12*$S12*(((1+secondaryInflation)^(secondaryInflationYear-Current_Fiscal_Year)) * ((1+X$7)^(X$8-(secondaryInflationYear - Current_Fiscal_Year)))),1)),"")),"") | Y12: =IFERROR(IF(OR(Y$8 = ($F12 - Current_Fiscal_Year),AND(MOD($F12-Y$9,$G12)=0,Y$9>$F12)),IF(secondaryInflationYear- Current_Fiscal_Year >=Y$8,ROUND($L12* $R12*$S12*((1 + Y$7)^Y$8),1),ROUND($L12* $R12*$S12*(((1+secondaryInflation)^(secondaryInflationYear-Current_Fiscal_Year)) * ((1+Y$7)^(Y$8-(secondaryInflationYear - Current_Fiscal_Year)))),1)),IF(AND($D12<>1,Y$8 > ($F12 - Current_Fiscal_Year),(Y$8 - (($F12 - Current_Fiscal_Year)+$G12*INT(((Y$8 - ($F12 - Current_Fiscal_Year)) / $G12))))/((($D12 - $E12)/($E12-1))+1) = INT((Y$8 - (($F12 - Current_Fiscal_Year)+$G12*INT(((Y$8 - ($F12 - Current_Fiscal_Year)) / $G12))))/((($D12 - $E12)/($E12-1))+1)), (Y$8 - (($F12 - Current_Fiscal_Year)+$G12*INT(((Y$8 - ($F12 - Current_Fiscal_Year)) / $G12)))) <$D12),IF(secondaryInflationYear- Current_Fiscal_Year >=Y$8,ROUND($L12* $R12*$S12*((1 + Y$7)^Y$8),1),ROUND($L12* $R12*$S12*(((1+secondaryInflation)^(secondaryInflationYear-Current_Fiscal_Year)) * ((1+Y$7)^(Y$8-(secondaryInflationYear - Current_Fiscal_Year)))),1)),"")),"") | Z12: =IFERROR(IF(OR(Z$8 = ($F12 - Current_Fiscal_Year),AND(MOD($F12-Z$9,$G12)=0,Z$9>$F12)),IF(secondaryInflationYear- Current_Fiscal_Year >=Z$8,ROUND($L12* $R12*$S12*((1 + Z$7)^Z$8),1),ROUND($L12* $R12*$S12*(((1+secondaryInflation)^(secondaryInflationYear-Current_Fiscal_Year)) * ((1+Z$7)^(Z$8-(secondaryInflationYear - Current_Fiscal_Year)))),1)),IF(AND($D12<>1,Z$8 > ($F12 - Current_Fiscal_Year),(Z$8 - (($F12 - Current_Fiscal_Year)+$G12*INT(((Z$8 - ($F12 - Current_Fiscal_Year)) / $G12))))/((($D12 - $E12)/($E12-1))+1) = INT((Z$8 - (($F12 - Current_Fiscal_Year)+$G12*INT(((Z$8 - ($F12 - Current_Fiscal_Year)) / $G12))))/((($D12 - $E12)/($E12-1))+1)), (Z$8 - (($F12 - Current_Fiscal_Year)+$G12*INT(((Z$8 - ($F12 - Current_Fiscal_Year)) / $G12)))) <$D12),IF(secondaryInflationYear- Current_Fiscal_Year >=Z$8,ROUND($L12* $R12*$S12*((1 + Z$7)^Z$8),1),ROUND($L12* $R12*$S12*(((1+secondaryInflation)^(secondaryInflationYear-Current_Fiscal_Year)) * ((1+Z$7)^(Z$8-(secondaryInflationYear - Current_Fiscal_Year)))),1)),"")),"") | AA12: =IFERROR(IF(OR(AA$8 = ($F12 - Current_Fiscal_Year),AND(MOD($F12-AA$9,$G12)=0,AA$9>$F12)),IF(secondaryInflationYear- Current_Fiscal_Year >=AA$8,ROUND($L12* $R12*$S12*((1 + AA$7)^AA$8),1),ROUND($L12* $R12*$S12*(((1+secondaryInflation)^(secondaryInflationYear-Current_Fiscal_Year)) * ((1+AA$7)^(AA$8-(secondaryInflationYear - Current_Fiscal_Year)))),1)),IF(AND($D12<>1,AA$8 > ($F12 - Current_Fiscal_Year),(AA$8 - (($F12 - Current_Fiscal_Year)+$G12*INT(((AA$8 - ($F12 - Current_Fiscal_Year)) / $G12))))/((($D12 - $E12)/($E12-1))+1) = INT((AA$8 - (($F12 - Current_Fiscal_Year)+$G12*INT(((AA$8 - ($F12 - Current_Fiscal_Year)) / $G12))))/((($D12 - $E12)/($E12-1))+1)), (AA$8 - (($F12 - Current_Fiscal_Year)+$G12*INT(((AA$8 - ($F12 - Current_Fiscal_Year)) / $G12)))) <$D12),IF(secondaryInflationYear- Current_Fiscal_Year >=AA$8,ROUND($L12* $R12*$S12*((1 + AA$7)^AA$8),1),ROUND($L12* $R12*$S12*(((1+secondaryInflation)^(secondaryInflationYear-Current_Fiscal_Year)) * ((1+AA$7)^(AA$8-(secondaryInflationYear - Current_Fiscal_Year)))),1)),"")),"") | AB12: =IFERROR(IF(OR(AB$8 = ($F12 - Current_Fiscal_Year),AND(MOD($F12-AB$9,$G12)=0,AB$9>$F12)),IF(secondaryInflationYear- Current_Fiscal_Year >=AB$8,ROUND($L12* $R12*$S12*((1 + AB$7)^AB$8),1),ROUND($L12* $R12*$S12*(((1+secondaryInflation)^(secondaryInflationYear-Current_Fiscal_Year)) * ((1+AB$7)^(AB$8-(secondaryInflationYear - Current_Fiscal_Year)))),1)),IF(AND($D12<>1,AB$8 > ($F12 - Current_Fiscal_Year),(AB$8 - (($F12 - Current_Fiscal_Year)+$G12*INT(((AB$8 - ($F12 - Current_Fiscal_Year)) / $G12))))/((($D12 - $E12)/($E12-1))+1) = INT((AB$8 - (($F12 - Current_Fiscal_Year)+$G12*INT(((AB$8 - ($F12 - Current_Fiscal_Year)) / $G12))))/((($D12 - $E12)/($E12-1))+1)), (AB$8 - (($F12 - Current_Fiscal_Year)+$G12*INT(((AB$8 - ($F12 - Current_Fiscal_Year)) / $G12)))) <$D12),IF(secondaryInflationYear- Current_Fiscal_Year >=AB$8,ROUND($L12* $R12*$S12*((1 + AB$7)^AB$8),1),ROUND($L12* $R12*$S12*(((1+secondaryInflation)^(secondaryInflationYear-Current_Fiscal_Year)) * ((1+AB$7)^(AB$8-(secondaryInflationYear - Current_Fiscal_Year)))),1)),"")),"") | AC12: =IFERROR(IF(OR(AC$8 = ($F12 - Current_Fiscal_Year),AND(MOD($F12-AC$9,$G12)=0,AC$9>$F12)),IF(secondaryInflationYear- Current_Fiscal_Year >=AC$8,ROUND($L12* $R12*$S12*((1 + AC$7)^AC$8),1),ROUND($L12* $R12*$S12*(((1+secondaryInflation)^(secondaryInflationYear-Current_Fiscal_Year)) * ((1+AC$7)^(AC$8-(secondaryInflationYear - Current_Fiscal_Year)))),1)),IF(AND($D12<>1,AC$8 > ($F12 - Current_Fiscal_Year),(AC$8 - (($F12 - Current_Fiscal_Year)+$G12*INT(((AC$8 - ($F12 - Current_Fiscal_Year)) / $G12))))/((($D12 - $E12)/($E12-1))+1) = INT((AC$8 - (($F12 - Current_Fiscal_Year)+$G12*INT(((AC$8 - ($F12 - Current_Fiscal_Year)) / $G12))))/((($D12 - $E12)/($E12-1))+1)), (AC$8 - (($F12 - Current_Fiscal_Year)+$G12*INT(((AC$8 - ($F12 - Current_Fiscal_Year)) / $G12)))) <$D12),IF(secondaryInflationYear- Current_Fiscal_Year >=AC$8,ROUND($L12* $R12*$S12*((1 + AC$7)^AC$8),1),ROUND($L12* $R12*$S12*(((1+secondaryInflation)^(secondaryInflationYear-Current_Fiscal_Year)) * ((1+AC$7)^(AC$8-(secondaryInflationYear - Current_Fiscal_Year)))),1)),"")),"") -> 14749.2 | AD12: =IFERROR(IF(OR(AD$8 = ($F12 - Current_Fiscal_Year),AND(MOD($F12-AD$9,$G12)=0,AD$9>$F12)),IF(secondaryInflationYear- Current_Fiscal_Year >=AD$8,ROUND($L12* $R12*$S12*((1 + AD$7)^AD$8),1),ROUND($L12* $R12*$S12*(((1+secondaryInflation)^(secondaryInflationYear-Current_Fiscal_Year)) * ((1+AD$7)^(AD$8-(secondaryInflationYear - Current_Fiscal_Year)))),1)),IF(AND($D12<>1,AD$8 > ($F12 - Current_Fiscal_Year),(AD$8 - (($F12 - Current_Fiscal_Year)+$G12*INT(((AD$8 - ($F12 - Current_Fiscal_Year)) / $G12))))/((($D12 - $E12)/($E12-1))+1) = INT((AD$8 - (($F12 - Current_Fiscal_Year)+$G12*INT(((AD$8 - ($F12 - Current_Fiscal_Year)) / $G12))))/((($D12 - $E12)/($E12-1))+1)), (AD$8 - (($F12 - Current_Fiscal_Year)+$G12*INT(((AD$8 - ($F12 - Current_Fiscal_Year)) / $G12)))) <$D12),IF(secondaryInflationYear- Current_Fiscal_Year >=AD$8,ROUND($L12* $R12*$S12*((1 + AD$7)^AD$8),1),ROUND($L12* $R12*$S12*(((1+secondaryInflation)^(secondaryInflationYear-Current_Fiscal_Year)) * ((1+AD$7)^(AD$8-(secondaryInflationYear - Current_Fiscal_Year)))),1)),"")),"") | AE12: =IFERROR(IF(OR(AE$8 = ($F12 - Current_Fiscal_Year),AND(MOD($F12-AE$9,$G12)=0,AE$9>$F12)),IF(secondaryInflationYear- Current_Fiscal_Year >=AE$8,ROUND($L12* $R12*$S12*((1 + AE$7)^AE$8),1),ROUND($L12* $R12*$S12*(((1+secondaryInflation)^(secondaryInflationYear-Current_Fiscal_Year)) * ((1+AE$7)^(AE$8-(secondaryInflationYear - Current_Fiscal_Year)))),1)),IF(AND($D12<>1,AE$8 > ($F12 - Current_Fiscal_Year),(AE$8 - (($F12 - Current_Fiscal_Year)+$G12*INT(((AE$8 - ($F12 - Current_Fiscal_Year)) / $G12))))/((($D12 - $E12)/($E12-1))+1) = INT((AE$8 - (($F12 - Current_Fiscal_Year)+$G12*INT(((AE$8 - ($F12 - Current_Fiscal_Year)) / $G12))))/((($D12 - $E12)/($E12-1))+1)), (AE$8 - (($F12 - Current_Fiscal_Year)+$G12*INT(((AE$8 - ($F12 - Current_Fiscal_Year)) / $G12)))) <$D12),IF(secondaryInflationYear- Current_Fiscal_Year >=AE$8,ROUND($L12* $R12*$S12*((1 + AE$7)^AE$8),1),ROUND($L12* $R12*$S12*(((1+secondaryInflation)^(secondaryInflationYear-Current_Fiscal_Year)) * ((1+AE$7)^(AE$8-(secondaryInflationYear - Current_Fiscal_Year)))),1)),"")),"") | ... AL12: =IFERROR(IF(OR(AL$8 = ($F12 - Current_Fiscal_Year),AND(MOD($F12-AL$9,$G12)=0,AL$9>$F12)),IF(secondaryInflationYear- Current_Fiscal_Year >=AL$8,ROUND($L12* $R12*$S12*((1 + AL$7)^AL$8),1),ROUND($L12* $R12*$S12*(((1+secondaryInflation)^(secondaryInflationYear-Current_Fiscal_Year)) * ((1+AL$7)^(AL$8-(secondaryInflationYear - Current_Fiscal_Year)))),1)),IF(AND($D12<>1,AL$8 > ($F12 - Current_Fiscal_Year),(AL$8 - (($F12 - Current_Fiscal_Year)+$G12*INT(((AL$8 - ($F12 - Current_Fiscal_Year)) / $G12))))/((($D12 - $E12)/($E12-1))+1) = INT((AL$8 - (($F12 - Current_Fiscal_Year)+$G12*INT(((AL$8 - ($F12 - Current_Fiscal_Year)) / $G12))))/((($D12 - $E12)/($E12-1))+1)), (AL$8 - (($F12 - Current_Fiscal_Year)+$G12*INT(((AL$8 - ($F12 - Current_Fiscal_Year)) / $G12)))) <$D12),IF(secondaryInflationYear- Current_Fiscal_Year >=AL$8,ROUND($L12* $R12*$S12*((1 + AL$7)^AL$8),1),ROUND($L12* $R12*$S12*(((1+secondaryInflation)^(secondaryInflationYear-Current_Fiscal_Year)) * ((1+AL$7)^(AL$8-(secondaryInflationYear - Current_Fiscal_Year)))),1)),"")),"") | AN12: =IFERROR(IF(OR(AN$8 = ($F12 - Current_Fiscal_Year),AND(MOD($F12-AN$9,$G12)=0,AN$9>$F12)),IF(secondaryInflationYear- Current_Fiscal_Year >=AN$8,ROUND($L12* $R12*$S12*((1 + AN$7)^AN$8),1),ROUND($L12* $R12*$S12*(((1+secondaryInflation)^(secondaryInflationYear-Current_Fiscal_Year)) * ((1+AN$7)^(AN$8-(secondaryInflationYear - Current_Fiscal_Year)))),1)),IF(AND($D12<>1,AN$8 > ($F12 - Current_Fiscal_Year),(AN$8 - (($F12 - Current_Fiscal_Year)+$G12*INT(((AN$8 - ($F12 - Current_Fiscal_Year)) / $G12))))/((($D12 - $E12)/($E12-1))+1) = INT((AN$8 - (($F12 - Current_Fiscal_Year)+$G12*INT(((AN$8 - ($F12 - Current_Fiscal_Year)) / $G12))))/((($D12 - $E12)/($E12-1))+1)), (AN$8 - (($F12 - Current_Fiscal_Year)+$G12*INT(((AN$8 - ($F12 - Current_Fiscal_Year)) / $G12)))) <$D12),IF(secondaryInflationYear- Current_Fiscal_Year >=AN$8,ROUND($L12* $R12*$S12*((1 + AN$7)^AN$8),1),ROUND($L12* $R12*$S12*(((1+secondaryInflation)^(secondaryInflationYear-Current_Fiscal_Year)) * ((1+AN$7)^(AN$8-(secondaryInflationYear - Current_Fiscal_Year)))),1)),"")),"") | AO12: =IFERROR(IF(OR(AO$8 = ($F12 - Current_Fiscal_Year),AND(MOD($F12-AO$9,$G12)=0,AO$9>$F12)),IF(secondaryInflationYear- Current_Fiscal_Year >=AO$8,ROUND($L12* $R12*$S12*((1 + AO$7)^AO$8),1),ROUND($L12* $R12*$S12*(((1+secondaryInflation)^(secondaryInflationYear-Current_Fiscal_Year)) * ((1+AO$7)^(AO$8-(secondaryInflationYear - Current_Fiscal_Year)))),1)),IF(AND($D12<>1,AO$8 > ($F12 - Current_Fiscal_Year),(AO$8 - (($F12 - Current_Fiscal_Year)+$G12*INT(((AO$8 - ($F12 - Current_Fiscal_Year)) / $G12))))/((($D12 - $E12)/($E12-1))+1) = INT((AO$8 - (($F12 - Current_Fiscal_Year)+$G12*INT(((AO$8 - ($F12 - Current_Fiscal_Year)) / $G12))))/((($D12 - $E12)/($E12-1))+1)), (AO$8 - (($F12 - Current_Fiscal_Year)+$G12*INT(((AO$8 - ($F12 - Current_Fiscal_Year)) / $G12)))) <$D12),IF(secondaryInflationYear- Current_Fiscal_Year >=AO$8,ROUND($L12* $R12*$S12*((1 + AO$7)^AO$8),1),ROUND($L12* $R12*$S12*(((1+secondaryInflation)^(secondaryInflationYear-Current_Fiscal_Year)) * ((1+AO$7)^(AO$8-(secondaryInflationYear - Current_Fiscal_Year)))),1)),"")),"") | AP12: =IFERROR(IF(OR(AP$8 = ($F12 - Current_Fiscal_Year),AND(MOD($F12-AP$9,$G12)=0,AP$9>$F12)),IF(secondaryInflationYear- Current_Fiscal_Year >=AP$8,ROUND($L12* $R12*$S12*((1 + AP$7)^AP$8),1),ROUND($L12* $R12*$S12*(((1+secondaryInflation)^(secondaryInflationYear-Current_Fiscal_Year)) * ((1+AP$7)^(AP$8-(secondaryInflationYear - Current_Fiscal_Year)))),1)),IF(AND($D12<>1,AP$8 > ($F12 - Current_Fiscal_Year),(AP$8 - (($F12 - Current_Fiscal_Year)+$G12*INT(((AP$8 - ($F12 - Current_Fiscal_Year)) / $G12))))/((($D12 - $E12)/($E12-1))+1) = INT((AP$8 - (($F12 - Current_Fiscal_Year)+$G12*INT(((AP$8 - ($F12 - Current_Fiscal_Year)) / $G12))))/((($D12 - $E12)/($E12-1))+1)), (AP$8 - (($F12 - Current_Fiscal_Year)+$G12*INT(((AP$8 - ($F12 - Current_Fiscal_Year)) / $G12)))) <$D12),IF(secondaryInflationYear- Current_Fiscal_Year >=AP$8,ROUND($L12* $R12*$S12*((1 + AP$7)^AP$8),1),ROUND($L12* $R12*$S12*(((1+secondaryInflation)^(secondaryInflationYear-Current_Fiscal_Year)) * ((1+AP$7)^(AP$8-(secondaryInflationYear - Current_Fiscal_Year)))),1)),"")),"") | AQ12: =IFERROR(IF(OR(AQ$8 = ($F12 - Current_Fiscal_Year),AND(MOD($F12-AQ$9,$G12)=0,AQ$9>$F12)),IF(secondaryInflationYear- Current_Fiscal_Year >=AQ$8,ROUND($L12* $R12*$S12*((1 + AQ$7)^AQ$8),1),ROUND($L12* $R12*$S12*(((1+secondaryInflation)^(secondaryInflationYear-Current_Fiscal_Year)) * ((1+AQ$7)^(AQ$8-(secondaryInflationYear - Current_Fiscal_Year)))),1)),IF(AND($D12<>1,AQ$8 > ($F12 - Current_Fiscal_Year),(AQ$8 - (($F12 - Current_Fiscal_Year)+$G12*INT(((AQ$8 - ($F12 - Current_Fiscal_Year)) / $G12))))/((($D12 - $E12)/($E12-1))+1) = INT((AQ$8 - (($F12 - Current_Fiscal_Year)+$G12*INT(((AQ$8 - ($F12 - Current_Fiscal_Year)) / $G12))))/((($D12 - $E12)/($E12-1))+1)), (AQ$8 - (($F12 - Current_Fiscal_Year)+$G12*INT(((AQ$8 - ($F12 - Current_Fiscal_Year)) / $G12)))) <$D12),IF(secondaryInflationYear- Current_Fiscal_Year >=AQ$8,ROUND($L12* $R12*$S12*((1 + AQ$7)^AQ$8),1),ROUND($L12* $R12*$S12*(((1+secondaryInflation)^(secondaryInflationYear-Current_Fiscal_Year)) * ((1+AQ$7)^(AQ$8-(secondaryInflationYear - Current_Fiscal_Year)))),1)),"")),"") | AR12: =IFERROR(IF(OR(AR$8 = ($F12 - Current_Fiscal_Year),AND(MOD($F12-AR$9,$G12)=0,AR$9>$F12)),IF(secondaryInflationYear- Current_Fiscal_Year >=AR$8,ROUND($L12* $R12*$S12*((1 + AR$7)^AR$8),1),ROUND($L12* $R12*$S12*(((1+secondaryInflation)^(secondaryInflationYear-Current_Fiscal_Year)) * ((1+AR$7)^(AR$8-(secondaryInflationYear - Current_Fiscal_Year)))),1)),IF(AND($D12<>1,AR$8 > ($F12 - Current_Fiscal_Year),(AR$8 - (($F12 - Current_Fiscal_Year)+$G12*INT(((AR$8 - ($F12 - Current_Fiscal_Year)) / $G12))))/((($D12 - $E12)/($E12-1))+1) = INT((AR$8 - (($F12 - Current_Fiscal_Year)+$G12*INT(((AR$8 - ($F12 - Current_Fiscal_Year)) / $G12))))/((($D12 - $E12)/($E12-1))+1)), (AR$8 - (($F12 - Current_Fiscal_Year)+$G12*INT(((AR$8 - ($F12 - Current_Fiscal_Year)) / $G12)))) <$D12),IF(secondaryInflationYear- Current_Fiscal_Year >=AR$8,ROUND($L12* $R12*$S12*((1 + AR$7)^AR$8),1),ROUND($L12* $R12*$S12*(((1+secondaryInflation)^(secondaryInflationYear-Current_Fiscal_Year)) * ((1+AR$7)^(AR$8-(secondaryInflationYear - Current_Fiscal_Year)))),1)),"")),"") -> 23657.3 | AS12: =IFERROR(IF(OR(AS$8 = ($F12 - Current_Fiscal_Year),AND(MOD($F12-AS$9,$G12)=0,AS$9>$F12)),IF(secondaryInflationYear- Current_Fiscal_Year >=AS$8,ROUND($L12* $R12*$S12*((1 + AS$7)^AS$8),1),ROUND($L12* $R12*$S12*(((1+secondaryInflation)^(secondaryInflationYear-Current_Fiscal_Year)) * ((1+AS$7)^(AS$8-(secondaryInflationYear - Current_Fiscal_Year)))),1)),IF(AND($D12<>1,AS$8 > ($F12 - Current_Fiscal_Year),(AS$8 - (($F12 - Current_Fiscal_Year)+$G12*INT(((AS$8 - ($F12 - Current_Fiscal_Year)) / $G12))))/((($D12 - $E12)/($E12-1))+1) = INT((AS$8 - (($F12 - Current_Fiscal_Year)+$G12*INT(((AS$8 - ($F12 - Current_Fiscal_Year)) / $G12))))/((($D12 - $E12)/($E12-1))+1)), (AS$8 - (($F12 - Current_Fiscal_Year)+$G12*INT(((AS$8 - ($F12 - Current_Fiscal_Year)) / $G12)))) <$D12),IF(secondaryInflationYear- Current_Fiscal_Year >=AS$8,ROUND($L12* $R12*$S12*((1 + AS$7)^AS$8),1),ROUND($L12* $R12*$S12*(((1+secondaryInflation)^(secondaryInflationYear-Current_Fiscal_Year)) * ((1+AS$7)^(AS$8-(secondaryInflationYear - Current_Fiscal_Year)))),1)),"")),"") | AT12: =IFERROR(IF(OR(AT$8 = ($F12 - Current_Fiscal_Year),AND(MOD($F12-AT$9,$G12)=0,AT$9>$F12)),IF(secondaryInflationYear- Current_Fiscal_Year >=AT$8,ROUND($L12* $R12*$S12*((1 + AT$7)^AT$8),1),ROUND($L12* $R12*$S12*(((1+secondaryInflation)^(secondaryInflationYear-Current_Fiscal_Year)) * ((1+AT$7)^(AT$8-(secondaryInflationYear - Current_Fiscal_Year)))),1)),IF(AND($D12<>1,AT$8 > ($F12 - Current_Fiscal_Year),(AT$8 - (($F12 - Current_Fiscal_Year)+$G12*INT(((AT$8 - ($F12 - Current_Fiscal_Year)) / $G12))))/((($D12 - $E12)/($E12-1))+1) = INT((AT$8 - (($F12 - Current_Fiscal_Year)+$G12*INT(((AT$8 - ($F12 - Current_Fiscal_Year)) / $G12))))/((($D12 - $E12)/($E12-1))+1)), (AT$8 - (($F12 - Current_Fiscal_Year)+$G12*INT(((AT$8 - ($F12 - Current_Fiscal_Year)) / $G12)))) <$D12),IF(secondaryInflationYear- Current_Fiscal_Year >=AT$8,ROUND($L12* $R12*$S12*((1 + AT$7)^AT$8),1),ROUND($L12* $R12*$S12*(((1+secondaryInflation)^(secondaryInflationYear-Current_Fiscal_Year)) * ((1+AT$7)^(AT$8-(secondaryInflationYear - Current_Fiscal_Year)))),1)),"")),"") | AU12: =IFERROR(IF(OR(AU$8 = ($F12 - Current_Fiscal_Year),AND(MOD($F12-AU$9,$G12)=0,AU$9>$F12)),IF(secondaryInflationYear- Current_Fiscal_Year >=AU$8,ROUND($L12* $R12*$S12*((1 + AU$7)^AU$8),1),ROUND($L12* $R12*$S12*(((1+secondaryInflation)^(secondaryInflationYear-Current_Fiscal_Year)) * ((1+AU$7)^(AU$8-(secondaryInflationYear - Current_Fiscal_Year)))),1)),IF(AND($D12<>1,AU$8 > ($F12 - Current_Fiscal_Year),(AU$8 - (($F12 - Current_Fiscal_Year)+$G12*INT(((AU$8 - ($F12 - Current_Fiscal_Year)) / $G12))))/((($D12 - $E12)/($E12-1))+1) = INT((AU$8 - (($F12 - Current_Fiscal_Year)+$G12*INT(((AU$8 - ($F12 - Current_Fiscal_Year)) / $G12))))/((($D12 - $E12)/($E12-1))+1)), (AU$8 - (($F12 - Current_Fiscal_Year)+$G12*INT(((AU$8 - ($F12 - Current_Fiscal_Year)) / $G12)))) <$D12),IF(secondaryInflationYear- Current_Fiscal_Year >=AU$8,ROUND($L12* $R12*$S12*((1 + AU$7)^AU$8),1),ROUND($L12* $R12*$S12*(((1+secondaryInflation)^(secondaryInflationYear-Current_Fiscal_Year)) * ((1+AU$7)^(AU$8-(secondaryInflationYear - Current_Fiscal_Year)))),1)),"")),"") | ... BB12: =IFERROR(IF(OR(BB$8 = ($F12 - Current_Fiscal_Year),AND(MOD($F12-BB$9,$G12)=0,BB$9>$F12)),IF(secondaryInflationYear- Current_Fiscal_Year >=BB$8,ROUND($L12* $R12*$S12*((1 + BB$7)^BB$8),1),ROUND($L12* $R12*$S12*(((1+secondaryInflation)^(secondaryInflationYear-Current_Fiscal_Year)) * ((1+BB$7)^(BB$8-(secondaryInflationYear - Current_Fiscal_Year)))),1)),IF(AND($D12<>1,BB$8 > ($F12 - Current_Fiscal_Year),(BB$8 - (($F12 - Current_Fiscal_Year)+$G12*INT(((BB$8 - ($F12 - Current_Fiscal_Year)) / $G12))))/((($D12 - $E12)/($E12-1))+1) = INT((BB$8 - (($F12 - Current_Fiscal_Year)+$G12*INT(((BB$8 - ($F12 - Current_Fiscal_Year)) / $G12))))/((($D12 - $E12)/($E12-1))+1)), (BB$8 - (($F12 - Current_Fiscal_Year)+$G12*INT(((BB$8 - ($F12 - Current_Fiscal_Year)) / $G12)))) <$D12),IF(secondaryInflationYear- Current_Fiscal_Year >=BB$8,ROUND($L12* $R12*$S12*((1 + BB$7)^BB$8),1),ROUND($L12* $R12*$S12*(((1+secondaryInflation)^(secondaryInflationYear-Current_Fiscal_Year)) * ((1+BB$7)^(BB$8-(secondaryInflationYear - Current_Fiscal_Year)))),1)),"")),"") -> 32416.2
A13: =IF(OFFSET($B13,IF(AND($K13=0,NOT(ISBLANK($K13))),-4,-3),-1)=0,1,0) -> 1 | B13: 1 | C13: 1 | D13: =(($E13-1)*$C13)+1 -> 1 | E13: 1 | F13: 2041 | G13: 25 | H13: 0.01 | J13: 4.04 | K13: 4200 | L13: =IF(M13="Allowance",1,ROUND(K13*B13/E13/H13,0)*H13) -> 4200 | M13: Square Yards | N13: Asphalt Pavement, Streets, Mill and Overlay | O13: =IF($F13>$BB$9,$F13,Current_Fiscal_Year+MATCH(TRUE,INDEX($X13:$BB13<>"",0),0)-1) -> 2041 | P13: 15 to 25 | Q13: =$O13-Current_Fiscal_Year&IF($B13<1," to "&Study_Length&"+",IF( $E13>1," to "&IF($O13-Current_Fiscal_Year+$D13-1>Study_Length,Study_Length&"+",$O13-Current_Fiscal_Year+$D13-1),"")) -> 15 | R13: 20 | S13: 1 | T13: =$L13*$R13*$S13 -> 84000 | U13: =$K13*$R13*$S13 -> 84000 | V13: =SUM(OFFSET($X13,,,1,Study_Length+1)) -> 134733.2 | W13: =$V13/Total_Study_Expenditures -> 0.16793358 | X13: =IFERROR(IF(OR(X$8 = ($F13 - Current_Fiscal_Year),AND(MOD($F13-X$9,$G13)=0,X$9>$F13)),IF(secondaryInflationYear- Current_Fiscal_Year >=X$8,ROUND($L13* $R13*$S13*((1 + X$7)^X$8),1),ROUND($L13* $R13*$S13*(((1+secondaryInflation)^(secondaryInflationYear-Current_Fiscal_Year)) * ((1+X$7)^(X$8-(secondaryInflationYear - Current_Fiscal_Year)))),1)),IF(AND($D13<>1,X$8 > ($F13 - Current_Fiscal_Year),(X$8 - (($F13 - Current_Fiscal_Year)+$G13*INT(((X$8 - ($F13 - Current_Fiscal_Year)) / $G13))))/((($D13 - $E13)/($E13-1))+1) = INT((X$8 - (($F13 - Current_Fiscal_Year)+$G13*INT(((X$8 - ($F13 - Current_Fiscal_Year)) / $G13))))/((($D13 - $E13)/($E13-1))+1)), (X$8 - (($F13 - Current_Fiscal_Year)+$G13*INT(((X$8 - ($F13 - Current_Fiscal_Year)) / $G13)))) <$D13),IF(secondaryInflationYear- Current_Fiscal_Year >=X$8,ROUND($L13* $R13*$S13*((1 + X$7)^X$8),1),ROUND($L13* $R13*$S13*(((1+secondaryInflation)^(secondaryInflationYear-Current_Fiscal_Year)) * ((1+X$7)^(X$8-(secondaryInflationYear - Current_Fiscal_Year)))),1)),"")),"") | Y13: =IFERROR(IF(OR(Y$8 = ($F13 - Current_Fiscal_Year),AND(MOD($F13-Y$9,$G13)=0,Y$9>$F13)),IF(secondaryInflationYear- Current_Fiscal_Year >=Y$8,ROUND($L13* $R13*$S13*((1 + Y$7)^Y$8),1),ROUND($L13* $R13*$S13*(((1+secondaryInflation)^(secondaryInflationYear-Current_Fiscal_Year)) * ((1+Y$7)^(Y$8-(secondaryInflationYear - Current_Fiscal_Year)))),1)),IF(AND($D13<>1,Y$8 > ($F13 - Current_Fiscal_Year),(Y$8 - (($F13 - Current_Fiscal_Year)+$G13*INT(((Y$8 - ($F13 - Current_Fiscal_Year)) / $G13))))/((($D13 - $E13)/($E13-1))+1) = INT((Y$8 - (($F13 - Current_Fiscal_Year)+$G13*INT(((Y$8 - ($F13 - Current_Fiscal_Year)) / $G13))))/((($D13 - $E13)/($E13-1))+1)), (Y$8 - (($F13 - Current_Fiscal_Year)+$G13*INT(((Y$8 - ($F13 - Current_Fiscal_Year)) / $G13)))) <$D13),IF(secondaryInflationYear- Current_Fiscal_Year >=Y$8,ROUND($L13* $R13*$S13*((1 + Y$7)^Y$8),1),ROUND($L13* $R13*$S13*(((1+secondaryInflation)^(secondaryInflationYear-Current_Fiscal_Year)) * ((1+Y$7)^(Y$8-(secondaryInflationYear - Current_Fiscal_Year)))),1)),"")),"") | Z13: =IFERROR(IF(OR(Z$8 = ($F13 - Current_Fiscal_Year),AND(MOD($F13-Z$9,$G13)=0,Z$9>$F13)),IF(secondaryInflationYear- Current_Fiscal_Year >=Z$8,ROUND($L13* $R13*$S13*((1 + Z$7)^Z$8),1),ROUND($L13* $R13*$S13*(((1+secondaryInflation)^(secondaryInflationYear-Current_Fiscal_Year)) * ((1+Z$7)^(Z$8-(secondaryInflationYear - Current_Fiscal_Year)))),1)),IF(AND($D13<>1,Z$8 > ($F13 - Current_Fiscal_Year),(Z$8 - (($F13 - Current_Fiscal_Year)+$G13*INT(((Z$8 - ($F13 - Current_Fiscal_Year)) / $G13))))/((($D13 - $E13)/($E13-1))+1) = INT((Z$8 - (($F13 - Current_Fiscal_Year)+$G13*INT(((Z$8 - ($F13 - Current_Fiscal_Year)) / $G13))))/((($D13 - $E13)/($E13-1))+1)), (Z$8 - (($F13 - Current_Fiscal_Year)+$G13*INT(((Z$8 - ($F13 - Current_Fiscal_Year)) / $G13)))) <$D13),IF(secondaryInflationYear- Current_Fiscal_Year >=Z$8,ROUND($L13* $R13*$S13*((1 + Z$7)^Z$8),1),ROUND($L13* $R13*$S13*(((1+secondaryInflation)^(secondaryInflationYear-Current_Fiscal_Year)) * ((1+Z$7)^(Z$8-(secondaryInflationYear - Current_Fiscal_Year)))),1)),"")),"") | AA13: =IFERROR(IF(OR(AA$8 = ($F13 - Current_Fiscal_Year),AND(MOD($F13-AA$9,$G13)=0,AA$9>$F13)),IF(secondaryInflationYear- Current_Fiscal_Year >=AA$8,ROUND($L13* $R13*$S13*((1 + AA$7)^AA$8),1),ROUND($L13* $R13*$S13*(((1+secondaryInflation)^(secondaryInflationYear-Current_Fiscal_Year)) * ((1+AA$7)^(AA$8-(secondaryInflationYear - Current_Fiscal_Year)))),1)),IF(AND($D13<>1,AA$8 > ($F13 - Current_Fiscal_Year),(AA$8 - (($F13 - Current_Fiscal_Year)+$G13*INT(((AA$8 - ($F13 - Current_Fiscal_Year)) / $G13))))/((($D13 - $E13)/($E13-1))+1) = INT((AA$8 - (($F13 - Current_Fiscal_Year)+$G13*INT(((AA$8 - ($F13 - Current_Fiscal_Year)) / $G13))))/((($D13 - $E13)/($E13-1))+1)), (AA$8 - (($F13 - Current_Fiscal_Year)+$G13*INT(((AA$8 - ($F13 - Current_Fiscal_Year)) / $G13)))) <$D13),IF(secondaryInflationYear- Current_Fiscal_Year >=AA$8,ROUND($L13* $R13*$S13*((1 + AA$7)^AA$8),1),ROUND($L13* $R13*$S13*(((1+secondaryInflation)^(secondaryInflationYear-Current_Fiscal_Year)) * ((1+AA$7)^(AA$8-(secondaryInflationYear - Current_Fiscal_Year)))),1)),"")),"") | AB13: =IFERROR(IF(OR(AB$8 = ($F13 - Current_Fiscal_Year),AND(MOD($F13-AB$9,$G13)=0,AB$9>$F13)),IF(secondaryInflationYear- Current_Fiscal_Year >=AB$8,ROUND($L13* $R13*$S13*((1 + AB$7)^AB$8),1),ROUND($L13* $R13*$S13*(((1+secondaryInflation)^(secondaryInflationYear-Current_Fiscal_Year)) * ((1+AB$7)^(AB$8-(secondaryInflationYear - Current_Fiscal_Year)))),1)),IF(AND($D13<>1,AB$8 > ($F13 - Current_Fiscal_Year),(AB$8 - (($F13 - Current_Fiscal_Year)+$G13*INT(((AB$8 - ($F13 - Current_Fiscal_Year)) / $G13))))/((($D13 - $E13)/($E13-1))+1) = INT((AB$8 - (($F13 - Current_Fiscal_Year)+$G13*INT(((AB$8 - ($F13 - Current_Fiscal_Year)) / $G13))))/((($D13 - $E13)/($E13-1))+1)), (AB$8 - (($F13 - Current_Fiscal_Year)+$G13*INT(((AB$8 - ($F13 - Current_Fiscal_Year)) / $G13)))) <$D13),IF(secondaryInflationYear- Current_Fiscal_Year >=AB$8,ROUND($L13* $R13*$S13*((1 + AB$7)^AB$8),1),ROUND($L13* $R13*$S13*(((1+secondaryInflation)^(secondaryInflationYear-Current_Fiscal_Year)) * ((1+AB$7)^(AB$8-(secondaryInflationYear - Current_Fiscal_Year)))),1)),"")),"") | AC13: =IFERROR(IF(OR(AC$8 = ($F13 - Current_Fiscal_Year),AND(MOD($F13-AC$9,$G13)=0,AC$9>$F13)),IF(secondaryInflationYear- Current_Fiscal_Year >=AC$8,ROUND($L13* $R13*$S13*((1 + AC$7)^AC$8),1),ROUND($L13* $R13*$S13*(((1+secondaryInflation)^(secondaryInflationYear-Current_Fiscal_Year)) * ((1+AC$7)^(AC$8-(secondaryInflationYear - Current_Fiscal_Year)))),1)),IF(AND($D13<>1,AC$8 > ($F13 - Current_Fiscal_Year),(AC$8 - (($F13 - Current_Fiscal_Year)+$G13*INT(((AC$8 - ($F13 - Current_Fiscal_Year)) / $G13))))/((($D13 - $E13)/($E13-1))+1) = INT((AC$8 - (($F13 - Current_Fiscal_Year)+$G13*INT(((AC$8 - ($F13 - Current_Fiscal_Year)) / $G13))))/((($D13 - $E13)/($E13-1))+1)), (AC$8 - (($F13 - Current_Fiscal_Year)+$G13*INT(((AC$8 - ($F13 - Current_Fiscal_Year)) / $G13)))) <$D13),IF(secondaryInflationYear- Current_Fiscal_Year >=AC$8,ROUND($L13* $R13*$S13*((1 + AC$7)^AC$8),1),ROUND($L13* $R13*$S13*(((1+secondaryInflation)^(secondaryInflationYear-Current_Fiscal_Year)) * ((1+AC$7)^(AC$8-(secondaryInflationYear - Current_Fiscal_Year)))),1)),"")),"") | AD13: =IFERROR(IF(OR(AD$8 = ($F13 - Current_Fiscal_Year),AND(MOD($F13-AD$9,$G13)=0,AD$9>$F13)),IF(secondaryInflationYear- Current_Fiscal_Year >=AD$8,ROUND($L13* $R13*$S13*((1 + AD$7)^AD$8),1),ROUND($L13* $R13*$S13*(((1+secondaryInflation)^(secondaryInflationYear-Current_Fiscal_Year)) * ((1+AD$7)^(AD$8-(secondaryInflationYear - Current_Fiscal_Year)))),1)),IF(AND($D13<>1,AD$8 > ($F13 - Current_Fiscal_Year),(AD$8 - (($F13 - Current_Fiscal_Year)+$G13*INT(((AD$8 - ($F13 - Current_Fiscal_Year)) / $G13))))/((($D13 - $E13)/($E13-1))+1) = INT((AD$8 - (($F13 - Current_Fiscal_Year)+$G13*INT(((AD$8 - ($F13 - Current_Fiscal_Year)) / $G13))))/((($D13 - $E13)/($E13-1))+1)), (AD$8 - (($F13 - Current_Fiscal_Year)+$G13*INT(((AD$8 - ($F13 - Current_Fiscal_Year)) / $G13)))) <$D13),IF(secondaryInflationYear- Current_Fiscal_Year >=AD$8,ROUND($L13* $R13*$S13*((1 + AD$7)^AD$8),1),ROUND($L13* $R13*$S13*(((1+secondaryInflation)^(secondaryInflationYear-Current_Fiscal_Year)) * ((1+AD$7)^(AD$8-(secondaryInflationYear - Current_Fiscal_Year)))),1)),"")),"") | AE13: =IFERROR(IF(OR(AE$8 = ($F13 - Current_Fiscal_Year),AND(MOD($F13-AE$9,$G13)=0,AE$9>$F13)),IF(secondaryInflationYear- Current_Fiscal_Year >=AE$8,ROUND($L13* $R13*$S13*((1 + AE$7)^AE$8),1),ROUND($L13* $R13*$S13*(((1+secondaryInflation)^(secondaryInflationYear-Current_Fiscal_Year)) * ((1+AE$7)^(AE$8-(secondaryInflationYear - Current_Fiscal_Year)))),1)),IF(AND($D13<>1,AE$8 > ($F13 - Current_Fiscal_Year),(AE$8 - (($F13 - Current_Fiscal_Year)+$G13*INT(((AE$8 - ($F13 - Current_Fiscal_Year)) / $G13))))/((($D13 - $E13)/($E13-1))+1) = INT((AE$8 - (($F13 - Current_Fiscal_Year)+$G13*INT(((AE$8 - ($F13 - Current_Fiscal_Year)) / $G13))))/((($D13 - $E13)/($E13-1))+1)), (AE$8 - (($F13 - Current_Fiscal_Year)+$G13*INT(((AE$8 - ($F13 - Current_Fiscal_Year)) / $G13)))) <$D13),IF(secondaryInflationYear- Current_Fiscal_Year >=AE$8,ROUND($L13* $R13*$S13*((1 + AE$7)^AE$8),1),ROUND($L13* $R13*$S13*(((1+secondaryInflation)^(secondaryInflationYear-Current_Fiscal_Year)) * ((1+AE$7)^(AE$8-(secondaryInflationYear - Current_Fiscal_Year)))),1)),"")),"") | ... BB13: =IFERROR(IF(OR(BB$8 = ($F13 - Current_Fiscal_Year),AND(MOD($F13-BB$9,$G13)=0,BB$9>$F13)),IF(secondaryInflationYear- Current_Fiscal_Year >=BB$8,ROUND($L13* $R13*$S13*((1 + BB$7)^BB$8),1),ROUND($L13* $R13*$S13*(((1+secondaryInflation)^(secondaryInflationYear-Current_Fiscal_Year)) * ((1+BB$7)^(BB$8-(secondaryInflationYear - Current_Fiscal_Year)))),1)),IF(AND($D13<>1,BB$8 > ($F13 - Current_Fiscal_Year),(BB$8 - (($F13 - Current_Fiscal_Year)+$G13*INT(((BB$8 - ($F13 - Current_Fiscal_Year)) / $G13))))/((($D13 - $E13)/($E13-1))+1) = INT((BB$8 - (($F13 - Current_Fiscal_Year)+$G13*INT(((BB$8 - ($F13 - Current_Fiscal_Year)) / $G13))))/((($D13 - $E13)/($E13-1))+1)), (BB$8 - (($F13 - Current_Fiscal_Year)+$G13*INT(((BB$8 - ($F13 - Current_Fiscal_Year)) / $G13)))) <$D13),IF(secondaryInflationYear- Current_Fiscal_Year >=BB$8,ROUND($L13* $R13*$S13*((1 + BB$7)^BB$8),1),ROUND($L13* $R13*$S13*(((1+secondaryInflation)^(secondaryInflationYear-Current_Fiscal_Year)) * ((1+BB$7)^(BB$8-(secondaryInflationYear - Current_Fiscal_Year)))),1)),"")),"")
A14: =IF(OFFSET($B14,IF(AND($K14=0,NOT(ISBLANK($K14))),-4,-3),-1)=0,1,0) -> 0 | B14: 0.3 | C14: 1 | D14: =(($E14-1)*$C14)+1 -> 1 | E14: 1 | F14: 2041 | G14: 25 | H14: 0.01 | J14: 4.11 | K14: 3200 | L14: =IF(M14="Allowance",1,ROUND(K14*B14/E14/H14,0)*H14) -> 960 | M14: Linear Feet | N14: Concrete Curbs and Gutters, Partial | O14: =IF($F14>$BB$9,$F14,Current_Fiscal_Year+MATCH(TRUE,INDEX($X14:$BB14<>"",0),0)-1) -> 2041 | P14: to 65 | Q14: =$O14-Current_Fiscal_Year&IF($B14<1," to "&Study_Length&"+",IF( $E14>1," to "&IF($O14-Current_Fiscal_Year+$D14-1>Study_Length,Study_Length&"+",$O14-Current_Fiscal_Year+$D14-1),"")) -> 15 to 30+ | R14: 40 | S14: 1 | T14: =$L14*$R14*$S14 -> 38400 | U14: =$K14*$R14*$S14 -> 128000 | V14: =SUM(OFFSET($X14,,,1,Study_Length+1)) -> 61592.3 | W14: =$V14/Total_Study_Expenditures -> 0.07676961 | X14: =IFERROR(IF(OR(X$8 = ($F14 - Current_Fiscal_Year),AND(MOD($F14-X$9,$G14)=0,X$9>$F14)),IF(secondaryInflationYear- Current_Fiscal_Year >=X$8,ROUND($L14* $R14*$S14*((1 + X$7)^X$8),1),ROUND($L14* $R14*$S14*(((1+secondaryInflation)^(secondaryInflationYear-Current_Fiscal_Year)) * ((1+X$7)^(X$8-(secondaryInflationYear - Current_Fiscal_Year)))),1)),IF(AND($D14<>1,X$8 > ($F14 - Current_Fiscal_Year),(X$8 - (($F14 - Current_Fiscal_Year)+$G14*INT(((X$8 - ($F14 - Current_Fiscal_Year)) / $G14))))/((($D14 - $E14)/($E14-1))+1) = INT((X$8 - (($F14 - Current_Fiscal_Year)+$G14*INT(((X$8 - ($F14 - Current_Fiscal_Year)) / $G14))))/((($D14 - $E14)/($E14-1))+1)), (X$8 - (($F14 - Current_Fiscal_Year)+$G14*INT(((X$8 - ($F14 - Current_Fiscal_Year)) / $G14)))) <$D14),IF(secondaryInflationYear- Current_Fiscal_Year >=X$8,ROUND($L14* $R14*$S14*((1 + X$7)^X$8),1),ROUND($L14* $R14*$S14*(((1+secondaryInflation)^(secondaryInflationYear-Current_Fiscal_Year)) * ((1+X$7)^(X$8-(secondaryInflationYear - Current_Fiscal_Year)))),1)),"")),"") | Y14: =IFERROR(IF(OR(Y$8 = ($F14 - Current_Fiscal_Year),AND(MOD($F14-Y$9,$G14)=0,Y$9>$F14)),IF(secondaryInflationYear- Current_Fiscal_Year >=Y$8,ROUND($L14* $R14*$S14*((1 + Y$7)^Y$8),1),ROUND($L14* $R14*$S14*(((1+secondaryInflation)^(secondaryInflationYear-Current_Fiscal_Year)) * ((1+Y$7)^(Y$8-(secondaryInflationYear - Current_Fiscal_Year)))),1)),IF(AND($D14<>1,Y$8 > ($F14 - Current_Fiscal_Year),(Y$8 - (($F14 - Current_Fiscal_Year)+$G14*INT(((Y$8 - ($F14 - Current_Fiscal_Year)) / $G14))))/((($D14 - $E14)/($E14-1))+1) = INT((Y$8 - (($F14 - Current_Fiscal_Year)+$G14*INT(((Y$8 - ($F14 - Current_Fiscal_Year)) / $G14))))/((($D14 - $E14)/($E14-1))+1)), (Y$8 - (($F14 - Current_Fiscal_Year)+$G14*INT(((Y$8 - ($F14 - Current_Fiscal_Year)) / $G14)))) <$D14),IF(secondaryInflationYear- Current_Fiscal_Year >=Y$8,ROUND($L14* $R14*$S14*((1 + Y$7)^Y$8),1),ROUND($L14* $R14*$S14*(((1+secondaryInflation)^(secondaryInflationYear-Current_Fiscal_Year)) * ((1+Y$7)^(Y$8-(secondaryInflationYear - Current_Fiscal_Year)))),1)),"")),"") | Z14: =IFERROR(IF(OR(Z$8 = ($F14 - Current_Fiscal_Year),AND(MOD($F14-Z$9,$G14)=0,Z$9>$F14)),IF(secondaryInflationYear- Current_Fiscal_Year >=Z$8,ROUND($L14* $R14*$S14*((1 + Z$7)^Z$8),1),ROUND($L14* $R14*$S14*(((1+secondaryInflation)^(secondaryInflationYear-Current_Fiscal_Year)) * ((1+Z$7)^(Z$8-(secondaryInflationYear - Current_Fiscal_Year)))),1)),IF(AND($D14<>1,Z$8 > ($F14 - Current_Fiscal_Year),(Z$8 - (($F14 - Current_Fiscal_Year)+$G14*INT(((Z$8 - ($F14 - Current_Fiscal_Year)) / $G14))))/((($D14 - $E14)/($E14-1))+1) = INT((Z$8 - (($F14 - Current_Fiscal_Year)+$G14*INT(((Z$8 - ($F14 - Current_Fiscal_Year)) / $G14))))/((($D14 - $E14)/($E14-1))+1)), (Z$8 - (($F14 - Current_Fiscal_Year)+$G14*INT(((Z$8 - ($F14 - Current_Fiscal_Year)) / $G14)))) <$D14),IF(secondaryInflationYear- Current_Fiscal_Year >=Z$8,ROUND($L14* $R14*$S14*((1 + Z$7)^Z$8),1),ROUND($L14* $R14*$S14*(((1+secondaryInflation)^(secondaryInflationYear-Current_Fiscal_Year)) * ((1+Z$7)^(Z$8-(secondaryInflationYear - Current_Fiscal_Year)))),1)),"")),"") | AA14: =IFERROR(IF(OR(AA$8 = ($F14 - Current_Fiscal_Year),AND(MOD($F14-AA$9,$G14)=0,AA$9>$F14)),IF(secondaryInflationYear- Current_Fiscal_Year >=AA$8,ROUND($L14* $R14*$S14*((1 + AA$7)^AA$8),1),ROUND($L14* $R14*$S14*(((1+secondaryInflation)^(secondaryInflationYear-Current_Fiscal_Year)) * ((1+AA$7)^(AA$8-(secondaryInflationYear - Current_Fiscal_Year)))),1)),IF(AND($D14<>1,AA$8 > ($F14 - Current_Fiscal_Year),(AA$8 - (($F14 - Current_Fiscal_Year)+$G14*INT(((AA$8 - ($F14 - Current_Fiscal_Year)) / $G14))))/((($D14 - $E14)/($E14-1))+1) = INT((AA$8 - (($F14 - Current_Fiscal_Year)+$G14*INT(((AA$8 - ($F14 - Current_Fiscal_Year)) / $G14))))/((($D14 - $E14)/($E14-1))+1)), (AA$8 - (($F14 - Current_Fiscal_Year)+$G14*INT(((AA$8 - ($F14 - Current_Fiscal_Year)) / $G14)))) <$D14),IF(secondaryInflationYear- Current_Fiscal_Year >=AA$8,ROUND($L14* $R14*$S14*((1 + AA$7)^AA$8),1),ROUND($L14* $R14*$S14*(((1+secondaryInflation)^(secondaryInflationYear-Current_Fiscal_Year)) * ((1+AA$7)^(AA$8-(secondaryInflationYear - Current_Fiscal_Year)))),1)),"")),"") | AB14: =IFERROR(IF(OR(AB$8 = ($F14 - Current_Fiscal_Year),AND(MOD($F14-AB$9,$G14)=0,AB$9>$F14)),IF(secondaryInflationYear- Current_Fiscal_Year >=AB$8,ROUND($L14* $R14*$S14*((1 + AB$7)^AB$8),1),ROUND($L14* $R14*$S14*(((1+secondaryInflation)^(secondaryInflationYear-Current_Fiscal_Year)) * ((1+AB$7)^(AB$8-(secondaryInflationYear - Current_Fiscal_Year)))),1)),IF(AND($D14<>1,AB$8 > ($F14 - Current_Fiscal_Year),(AB$8 - (($F14 - Current_Fiscal_Year)+$G14*INT(((AB$8 - ($F14 - Current_Fiscal_Year)) / $G14))))/((($D14 - $E14)/($E14-1))+1) = INT((AB$8 - (($F14 - Current_Fiscal_Year)+$G14*INT(((AB$8 - ($F14 - Current_Fiscal_Year)) / $G14))))/((($D14 - $E14)/($E14-1))+1)), (AB$8 - (($F14 - Current_Fiscal_Year)+$G14*INT(((AB$8 - ($F14 - Current_Fiscal_Year)) / $G14)))) <$D14),IF(secondaryInflationYear- Current_Fiscal_Year >=AB$8,ROUND($L14* $R14*$S14*((1 + AB$7)^AB$8),1),ROUND($L14* $R14*$S14*(((1+secondaryInflation)^(secondaryInflationYear-Current_Fiscal_Year)) * ((1+AB$7)^(AB$8-(secondaryInflationYear - Current_Fiscal_Year)))),1)),"")),"") | AC14: =IFERROR(IF(OR(AC$8 = ($F14 - Current_Fiscal_Year),AND(MOD($F14-AC$9,$G14)=0,AC$9>$F14)),IF(secondaryInflationYear- Current_Fiscal_Year >=AC$8,ROUND($L14* $R14*$S14*((1 + AC$7)^AC$8),1),ROUND($L14* $R14*$S14*(((1+secondaryInflation)^(secondaryInflationYear-Current_Fiscal_Year)) * ((1+AC$7)^(AC$8-(secondaryInflationYear - Current_Fiscal_Year)))),1)),IF(AND($D14<>1,AC$8 > ($F14 - Current_Fiscal_Year),(AC$8 - (($F14 - Current_Fiscal_Year)+$G14*INT(((AC$8 - ($F14 - Current_Fiscal_Year)) / $G14))))/((($D14 - $E14)/($E14-1))+1) = INT((AC$8 - (($F14 - Current_Fiscal_Year)+$G14*INT(((AC$8 - ($F14 - Current_Fiscal_Year)) / $G14))))/((($D14 - $E14)/($E14-1))+1)), (AC$8 - (($F14 - Current_Fiscal_Year)+$G14*INT(((AC$8 - ($F14 - Current_Fiscal_Year)) / $G14)))) <$D14),IF(secondaryInflationYear- Current_Fiscal_Year >=AC$8,ROUND($L14* $R14*$S14*((1 + AC$7)^AC$8),1),ROUND($L14* $R14*$S14*(((1+secondaryInflation)^(secondaryInflationYear-Current_Fiscal_Year)) * ((1+AC$7)^(AC$8-(secondaryInflationYear - Current_Fiscal_Year)))),1)),"")),"") | AD14: =IFERROR(IF(OR(AD$8 = ($F14 - Current_Fiscal_Year),AND(MOD($F14-AD$9,$G14)=0,AD$9>$F14)),IF(secondaryInflationYear- Current_Fiscal_Year >=AD$8,ROUND($L14* $R14*$S14*((1 + AD$7)^AD$8),1),ROUND($L14* $R14*$S14*(((1+secondaryInflation)^(secondaryInflationYear-Current_Fiscal_Year)) * ((1+AD$7)^(AD$8-(secondaryInflationYear - Current_Fiscal_Year)))),1)),IF(AND($D14<>1,AD$8 > ($F14 - Current_Fiscal_Year),(AD$8 - (($F14 - Current_Fiscal_Year)+$G14*INT(((AD$8 - ($F14 - Current_Fiscal_Year)) / $G14))))/((($D14 - $E14)/($E14-1))+1) = INT((AD$8 - (($F14 - Current_Fiscal_Year)+$G14*INT(((AD$8 - ($F14 - Current_Fiscal_Year)) / $G14))))/((($D14 - $E14)/($E14-1))+1)), (AD$8 - (($F14 - Current_Fiscal_Year)+$G14*INT(((AD$8 - ($F14 - Current_Fiscal_Year)) / $G14)))) <$D14),IF(secondaryInflationYear- Current_Fiscal_Year >=AD$8,ROUND($L14* $R14*$S14*((1 + AD$7)^AD$8),1),ROUND($L14* $R14*$S14*(((1+secondaryInflation)^(secondaryInflationYear-Current_Fiscal_Year)) * ((1+AD$7)^(AD$8-(secondaryInflationYear - Current_Fiscal_Year)))),1)),"")),"") | AE14: =IFERROR(IF(OR(AE$8 = ($F14 - Current_Fiscal_Year),AND(MOD($F14-AE$9,$G14)=0,AE$9>$F14)),IF(secondaryInflationYear- Current_Fiscal_Year >=AE$8,ROUND($L14* $R14*$S14*((1 + AE$7)^AE$8),1),ROUND($L14* $R14*$S14*(((1+secondaryInflation)^(secondaryInflationYear-Current_Fiscal_Year)) * ((1+AE$7)^(AE$8-(secondaryInflationYear - Current_Fiscal_Year)))),1)),IF(AND($D14<>1,AE$8 > ($F14 - Current_Fiscal_Year),(AE$8 - (($F14 - Current_Fiscal_Year)+$G14*INT(((AE$8 - ($F14 - Current_Fiscal_Year)) / $G14))))/((($D14 - $E14)/($E14-1))+1) = INT((AE$8 - (($F14 - Current_Fiscal_Year)+$G14*INT(((AE$8 - ($F14 - Current_Fiscal_Year)) / $G14))))/((($D14 - $E14)/($E14-1))+1)), (AE$8 - (($F14 - Current_Fiscal_Year)+$G14*INT(((AE$8 - ($F14 - Current_Fiscal_Year)) / $G14)))) <$D14),IF(secondaryInflationYear- Current_Fiscal_Year >=AE$8,ROUND($L14* $R14*$S14*((1 + AE$7)^AE$8),1),ROUND($L14* $R14*$S14*(((1+secondaryInflation)^(secondaryInflationYear-Current_Fiscal_Year)) * ((1+AE$7)^(AE$8-(secondaryInflationYear - Current_Fiscal_Year)))),1)),"")),"") | ... BB14: =IFERROR(IF(OR(BB$8 = ($F14 - Current_Fiscal_Year),AND(MOD($F14-BB$9,$G14)=0,BB$9>$F14)),IF(secondaryInflationYear- Current_Fiscal_Year >=BB$8,ROUND($L14* $R14*$S14*((1 + BB$7)^BB$8),1),ROUND($L14* $R14*$S14*(((1+secondaryInflation)^(secondaryInflationYear-Current_Fiscal_Year)) * ((1+BB$7)^(BB$8-(secondaryInflationYear - Current_Fiscal_Year)))),1)),IF(AND($D14<>1,BB$8 > ($F14 - Current_Fiscal_Year),(BB$8 - (($F14 - Current_Fiscal_Year)+$G14*INT(((BB$8 - ($F14 - Current_Fiscal_Year)) / $G14))))/((($D14 - $E14)/($E14-1))+1) = INT((BB$8 - (($F14 - Current_Fiscal_Year)+$G14*INT(((BB$8 - ($F14 - Current_Fiscal_Year)) / $G14))))/((($D14 - $E14)/($E14-1))+1)), (BB$8 - (($F14 - Current_Fiscal_Year)+$G14*INT(((BB$8 - ($F14 - Current_Fiscal_Year)) / $G14)))) <$D14),IF(secondaryInflationYear- Current_Fiscal_Year >=BB$8,ROUND($L14* $R14*$S14*((1 + BB$7)^BB$8),1),ROUND($L14* $R14*$S14*(((1+secondaryInflation)^(secondaryInflationYear-Current_Fiscal_Year)) * ((1+BB$7)^(BB$8-(secondaryInflationYear - Current_Fiscal_Year)))),1)),"")),"")
